<?xml version="1.0" ?>
<!-- =================================================================================== -->
<!-- |    This document was autogenerated by xacro from robotino.urdf.xacro            | -->
<!-- |    EDITING THIS FILE BY HAND IS NOT RECOMMENDED                                 | -->
<!-- =================================================================================== -->
<robot name="robot" xmlns:xacro="http://www.ros.org/wiki/xacro">
  <!-- ****************** -->
  <!-- ***** COMMON ***** -->
  <!-- ****************** -->
  <!-- hokuyo mount positions | relative to base_link -->
  <!-- pan_tilt mount positions | handeye calibration | relative to base_link -->
  <!--property name="pan_tilt_x" value="0.310911"/>
  <property name="pan_tilt_y" value="0.0177173"/>
  <property name="pan_tilt_z" value="0.683637"/>
  <property name="pan_tilt_roll" value="3.0864"/>
  <property name="pan_tilt_pitch" value="3.08658"/>
  <property name="pan_tilt_yaw" value="3.13856"/-->
  <!-- kinect mount positions | handeye calibration | relative to pan_tilt_link -->
  <!--property name="kinect_x" value="0.0162762"/>
  <property name="kinect_y" value="0.0736591"/>
  <property name="kinect_z" value="-0.0649505"/>
  <property name="kinect_roll" value="-1.53"/>
  <property name="kinect_pitch" value="-0.0315698"/>
  <property name="kinect_yaw" value="0.0239961"/-->
  <!-- pan_tilt mount positions | handeye calibration | relative to base_link -->
  <!-- kinect mount positions | handeye calibration | relative to pan_tilt_link -->
  <!-- pan_tilt mount positions | handeye calibration | relative to base_link -->
  <!--property name="pan_tilt_x" value="0.257201"/>
  <property name="pan_tilt_y" value="0.0587815"/>
  <property name="pan_tilt_z" value="0.637117"/>
  <property name="pan_tilt_roll" value="0.012045"/>
  <property name="pan_tilt_pitch" value="-0.0565489"/>
  <property name="pan_tilt_yaw" value="0.0113182"/-->
  <!-- kinect mount positions | handeye calibration | relative to pan_tilt_link -->
  <!--property name="kinect_x" value="0.0772857"/>
  <property name="kinect_y" value="0.117459"/>
  <property name="kinect_z" value="-0.0273189"/>
  <property name="kinect_roll" value="1.57297"/>
  <property name="kinect_pitch" value="-3.11833"/>
  <property name="kinect_yaw" value="3.10173"/-->
  <!-- arm mount positions | handeye calibration | relative to base_link -->
  <!-- arm calibration-->
  <!-- WHEEL -->
  <!--GAZEBO PLUGIN-->
  <!-- GAZEBO OPENNI PLUGIN -->
  <!--###### IF 8 DOF the joints can be moved ######-->
  <!--###### ELSE the joints are fixed ######-->
  <link name="base_link"/>
  <joint name="base_body_joint" type="fixed">
    <parent link="base_link"/>
    <child link="base_body_link"/>
    <origin rpy="0 0 0" xyz="0 0 0"/>
  </joint>
  <link name="base_body_link">
    <inertial>
      <mass value="10"/>
      <origin xyz="0 0 0"/>
      <inertia ixx="75.0" ixy="0.0" ixz="0.0" iyy="75.0" iyz="0.0" izz="75.0"/>
    </inertial>
    <visual>
      <origin rpy="0 0 0" xyz="0.01 0 0"/>
      <geometry>
        <mesh filename="package://robotino_description/meshes/RobotinoBody.dae"/>
      </geometry>
    </visual>
    <collision>
      <origin rpy="0 0 0" xyz="0.01 0 0"/>
      <geometry>
        <mesh filename="package://robotino_description/meshes/RobotinoBody.stl"/>
      </geometry>
    </collision>
  </link>
  <gravity>true</gravity>
  <self_collide>false</self_collide>
  <joint name="arm_base_joint" type="fixed">
    <parent link="base_link"/>
    <child link="arm_base_link"/>
    <axis xyz="0 0 1"/>
    <origin rpy="0.0 0.0 -1" xyz="0.0 -0.01591 0.32"/>
  </joint>
  <link name="arm_base_link">
    <inertial>
      <mass value="0.01"/>
      <origin xyz="0 0 0"/>
      <inertia ixx="0.001" ixy="0.0" ixz="0.0" iyy="0.001" iyz="0.0" izz="0.001"/>
    </inertial>
    <visual>
      <geometry>
        <mesh filename="package://robotino_description/meshes/arm/link0.stl"/>
      </geometry>
      <material name="white">
        <color rgba="1 1 1 1"/>
      </material>
      <origin rpy="0 0 0" xyz="0 0 0."/>
    </visual>
    <collision>
      <origin rpy="0 0 0" xyz="0 0 0."/>
      <geometry>
        <mesh filename="package://robotino_description/meshes/arm/link0_collision.stl"/>
      </geometry>
    </collision>
  </link>
  <joint name="arm_joint1" type="revolute">
    <parent link="arm_base_link"/>
    <child link="arm_link1"/>
    <origin rpy="0 0 0" xyz="0.0 0.0 0.0"/>
    <axis xyz="0 1 0"/>
    <limit effort="190" lower="-1.9" upper="1.9" velocity="30"/>
  </joint>
  <link name="arm_link1">
    <inertial>
      <mass value="0.01"/>
      <origin xyz="0 0 0"/>
      <inertia ixx="0.001" ixy="0.0" ixz="0.0" iyy="0.001" iyz="0.0" izz="0.001"/>
    </inertial>
    <visual>
      <geometry>
        <mesh filename="package://robotino_description/meshes/arm/link1.stl"/>
      </geometry>
      <material name="white"/>
      <origin rpy="0 0 0" xyz="0 0 0"/>
    </visual>
    <collision>
      <origin rpy="0 0 0" xyz="0 0 0"/>
      <geometry>
        <mesh filename="package://robotino_description/meshes/arm/link1_collision.stl"/>
      </geometry>
    </collision>
  </link>
  <joint name="arm_joint2" type="revolute">
    <parent link="arm_link1"/>
    <child link="arm_motor2"/>
    <origin rpy="0 0 0" xyz="0.0 0.0 0.25"/>
    <axis xyz="0 1 0"/>
    <limit effort="190" lower="-1.9" upper="1.9" velocity="30"/>
  </joint>
  <link name="arm_motor2">
    <inertial>
      <mass value="0.01"/>
      <origin xyz="0 0 0"/>
      <inertia ixx="0.001" ixy="0.0" ixz="0.0" iyy="0.001" iyz="0.0" izz="0.001"/>
    </inertial>
    <visual>
      <geometry>
        <box size="0 0 0"/>
      </geometry>
      <material name="white"/>
      <origin rpy="0 0 0" xyz="0 0.0625 0."/>
    </visual>
  </link>
  <joint name="fixed_motor2_link2" type="fixed">
    <parent link="arm_motor2"/>
    <child link="arm_link2"/>
    <origin rpy="0 0 0" xyz="0.0 0.098 0.027"/>
  </joint>
  <link name="arm_link2">
    <inertial>
      <mass value="0.01"/>
      <origin xyz="0 0 0"/>
      <inertia ixx="0.001" ixy="0.0" ixz="0.0" iyy="0.001" iyz="0.0" izz="0.001"/>
    </inertial>
    <visual>
      <geometry>
        <mesh filename="package://robotino_description/meshes/arm/link2.stl"/>
      </geometry>
      <material name="white"/>
      <origin rpy="0 0 0" xyz="0 0 0"/>
    </visual>
    <collision>
      <origin rpy="0 0 0" xyz="0 0 0"/>
      <geometry>
        <mesh filename="package://robotino_description/meshes/arm/link2_collision.stl"/>
      </geometry>
    </collision>
  </link>
  <joint name="arm_joint3" type="revolute">
    <parent link="arm_link2"/>
    <child link="arm_link3"/>
    <origin rpy="0 0 0" xyz="0.0 0.0 0.158"/>
    <axis xyz="0 0 1"/>
    <limit effort="190" lower="-1.7" upper="1.7" velocity="30"/>
  </joint>
  <link name="arm_link3">
    <inertial>
      <mass value="0.01"/>
      <origin xyz="0 0 0"/>
      <inertia ixx="0.001" ixy="0.0" ixz="0.0" iyy="0.001" iyz="0.0" izz="0.001"/>
    </inertial>
    <visual>
      <geometry>
        <mesh filename="package://robotino_description/meshes/arm/link3.stl"/>
      </geometry>
      <material name="white"/>
      <origin rpy="0 0 0" xyz="0 0 0"/>
    </visual>
    <collision>
      <origin rpy="0 0 0" xyz="0 0 0"/>
      <geometry>
        <mesh filename="package://robotino_description/meshes/arm/link3_collision.stl"/>
      </geometry>
    </collision>
  </link>
  <joint name="arm_joint4" type="revolute">
    <parent link="arm_link3"/>
    <child link="arm_link4"/>
    <origin rpy="0 0 0" xyz="0.0 -0.057 0.065"/>
    <axis xyz="0 1 0"/>
    <limit effort="160" lower="-1.7" upper="1.7" velocity="30"/>
  </joint>
  <link name="arm_link4">
    <inertial>
      <mass value="0.01"/>
      <origin xyz="0 0 0"/>
      <inertia ixx="0.001" ixy="0.0" ixz="0.0" iyy="0.001" iyz="0.0" izz="0.001"/>
    </inertial>
    <visual>
      <geometry>
        <mesh filename="package://robotino_description/meshes/arm/link4.stl"/>
      </geometry>
      <material name="white"/>
      <origin rpy="0 0 0" xyz="0 0 0"/>
    </visual>
    <collision>
      <origin rpy="0 0 0" xyz="0 0 0"/>
      <geometry>
        <mesh filename="package://robotino_description/meshes/arm/link4_collision.stl"/>
      </geometry>
    </collision>
  </link>
  <joint name="arm_joint5" type="revolute">
    <parent link="arm_link4"/>
    <child link="arm_link5"/>
    <origin rpy="0 0 0" xyz="0.0 -0.027 0.035"/>
    <axis xyz="0 0 1"/>
    <limit effort="160" lower="-1.7" upper="1.7" velocity="30"/>
  </joint>
  <link name="arm_link5">
    <inertial>
      <mass value="0.01"/>
      <origin xyz="0 0 0"/>
      <inertia ixx="0.001" ixy="0.0" ixz="0.0" iyy="0.001" iyz="0.0" izz="0.001"/>
    </inertial>
  </link>
  <joint name="hand_wrist_joint" type="fixed">
    <origin rpy="1.5707963 0 0" xyz="0 0 0"/>
    <parent link="arm_link5"/>
    <child link="hand_wrist_link"/>
  </joint>
  <link name="hand_wrist_link">
    <inertial>
      <mass value="0.01"/>
      <origin xyz="0 0 0"/>
      <inertia ixx="0.001" ixy="0.0" ixz="0.0" iyy="0.001" iyz="0.0" izz="0.001"/>
    </inertial>
    <visual>
      <origin rpy="0 0 0" xyz="0 0 0"/>
      <geometry>
        <mesh filename="package://robotino_description/meshes/kclhand/wrist.stl"/>
      </geometry>
      <material name="">
        <color rgba="0.79216 0.81961 0.93333 1"/>
      </material>
    </visual>
    <collision>
      <origin rpy="0 0 0" xyz="0 0 0"/>
      <geometry>
        <mesh filename="package://robotino_description/meshes/kclhand/wrist.stl"/>
      </geometry>
    </collision>
  </link>
  <joint name="hand_base_joint" type="fixed">
    <origin rpy="0 0.52 0" xyz="-0.02105 0.1485 0"/>
    <parent link="hand_wrist_link"/>
    <child link="hand_base_link"/>
  </joint>
  <link name="hand_base_link">
    <inertial>
      <mass value="0.01"/>
      <origin xyz="0 0 0"/>
      <inertia ixx="0.001" ixy="0.0" ixz="0.0" iyy="0.001" iyz="0.0" izz="0.001"/>
    </inertial>
    <visual>
      <origin rpy="0 0 0" xyz="0 0 0"/>
      <geometry>
        <mesh filename="package://robotino_description/meshes/kclhand/base_link.STL"/>
      </geometry>
      <material name="">
        <color rgba="0.79216 0.81961 0.93333 1"/>
      </material>
    </visual>
    <collision>
      <origin rpy="0 0 0" xyz="0 0 0"/>
      <geometry>
        <mesh filename="package://robotino_description/meshes/kclhand/base_link.STL"/>
      </geometry>
    </collision>
  </link>
  <joint name="hand_middle_finger_lower_joint" type="continuous">
    <origin rpy="-0.5236 5.5511E-17 1.5708" xyz="0.035507 0.02 0.0205"/>
    <parent link="hand_base_link"/>
    <child link="hand_middle_finger_lower_link"/>
    <axis xyz="0 0 -1"/>
  </joint>
  <link name="hand_middle_finger_lower_link">
    <inertial>
      <mass value="0.01"/>
      <origin xyz="0 0 0"/>
      <inertia ixx="0.001" ixy="0.0" ixz="0.0" iyy="0.001" iyz="0.0" izz="0.001"/>
    </inertial>
    <visual>
      <origin rpy="0 0 0" xyz="0 0 0"/>
      <geometry>
        <mesh filename="package://robotino_description/meshes/kclhand/middle_finger_lower_link.STL"/>
      </geometry>
      <material name="">
        <color rgba="0.79216 0.81961 0.93333 1"/>
      </material>
    </visual>
    <collision>
      <origin rpy="0 0 0" xyz="0 0 0"/>
      <geometry>
        <mesh filename="package://robotino_description/meshes/kclhand/middle_finger_lower_link.STL"/>
      </geometry>
    </collision>
  </link>
  <joint name="hand_middle_finger_upper_joint" type="continuous">
    <origin rpy="0 0 0.7854" xyz="0.05 0 0"/>
    <parent link="hand_middle_finger_lower_link"/>
    <child link="hand_middle_finger_upper_link"/>
    <axis xyz="0 0 1"/>
  </joint>
  <link name="hand_middle_finger_upper_link">
    <inertial>
      <mass value="0.01"/>
      <origin xyz="0 0 0"/>
      <inertia ixx="0.001" ixy="0.0" ixz="0.0" iyy="0.001" iyz="0.0" izz="0.001"/>
    </inertial>
    <visual>
      <origin rpy="0 0 0" xyz="0 0 0"/>
      <geometry>
        <mesh filename="package://robotino_description/meshes/kclhand/middle_finger_upper_link.STL"/>
      </geometry>
      <material name="">
        <color rgba="0.79216 0.81961 0.93333 1"/>
      </material>
    </visual>
    <collision>
      <origin rpy="0 0 0" xyz="0 0 0"/>
      <geometry>
        <mesh filename="package://robotino_description/meshes/kclhand/middle_finger_upper_link.STL"/>
      </geometry>
    </collision>
  </link>
  <joint name="hand_left_crank_base_joint" type="continuous">
    <origin rpy="-2.1588 0.44783 -1.8518" xyz="0 0 0"/>
    <parent link="hand_base_link"/>
    <child link="hand_left_crank"/>
    <axis xyz="0 0 1"/>
  </joint>
  <link name="hand_left_crank">
    <inertial>
      <mass value="0.01"/>
      <origin xyz="0 0 0"/>
      <inertia ixx="0.001" ixy="0.0" ixz="0.0" iyy="0.001" iyz="0.0" izz="0.001"/>
    </inertial>
    <visual>
      <origin rpy="0 0 0" xyz="0 0 0"/>
      <geometry>
        <mesh filename="package://robotino_description/meshes/kclhand/left_crank.STL"/>
      </geometry>
      <material name="">
        <color rgba="0.79216 0.81961 0.93333 1"/>
      </material>
    </visual>
    <collision>
      <origin rpy="0 0 0" xyz="0 0 0"/>
      <geometry>
        <mesh filename="package://robotino_description/meshes/kclhand/left_crank.STL"/>
      </geometry>
    </collision>
  </link>
  <joint name="hand_left_coupler_crank_joint" type="continuous">
    <origin rpy="0.40154 0.63113 0.62376" xyz="0 0 0"/>
    <parent link="hand_left_crank"/>
    <child link="hand_left_coupler"/>
    <axis xyz="0 0 1"/>
  </joint>
  <link name="hand_left_coupler">
    <inertial>
      <mass value="0.01"/>
      <origin xyz="0 0 0"/>
      <inertia ixx="0.001" ixy="0.0" ixz="0.0" iyy="0.001" iyz="0.0" izz="0.001"/>
    </inertial>
    <visual>
      <origin rpy="0 0 0" xyz="0 0 0"/>
      <geometry>
        <mesh filename="package://robotino_description/meshes/kclhand/left_coupler.STL"/>
      </geometry>
      <material name="">
        <color rgba="0.79216 0.81961 0.93333 1"/>
      </material>
    </visual>
    <collision>
      <origin rpy="0 0 0" xyz="0 0 0"/>
      <geometry>
        <mesh filename="package://robotino_description/meshes/kclhand/left_coupler.STL"/>
      </geometry>
    </collision>
  </link>
  <joint name="hand_left_finger_lower_joint" type="continuous">
    <origin rpy="-1.2217 -7.6328E-17 1.5708" xyz="0.016246 0.021 0.044635"/>
    <parent link="hand_left_coupler"/>
    <child link="hand_left_finger_lower_link"/>
    <axis xyz="0 0 -1"/>
  </joint>
  <link name="hand_left_finger_lower_link">
    <inertial>
      <mass value="0.01"/>
      <origin xyz="0 0 0"/>
      <inertia ixx="0.001" ixy="0.0" ixz="0.0" iyy="0.001" iyz="0.0" izz="0.001"/>
    </inertial>
    <visual>
      <origin rpy="0 0 0" xyz="0 0 0"/>
      <geometry>
        <mesh filename="package://robotino_description/meshes/kclhand/left_finger_lower_link.STL"/>
      </geometry>
      <material name="">
        <color rgba="0.79216 0.81961 0.93333 1"/>
      </material>
    </visual>
    <collision>
      <origin rpy="0 0 0" xyz="0 0 0"/>
      <geometry>
        <mesh filename="package://robotino_description/meshes/kclhand/left_finger_lower_link.STL"/>
      </geometry>
    </collision>
  </link>
  <joint name="hand_left_finger_upper_joint" type="continuous">
    <origin rpy="-1.5543E-15 7.7716E-16 0.7854" xyz="0.05 0 0"/>
    <parent link="hand_left_finger_lower_link"/>
    <child link="hand_left_finger_upper_link"/>
    <axis xyz="0 0 1"/>
  </joint>
  <link name="hand_left_finger_upper_link">
    <inertial>
      <mass value="0.01"/>
      <origin xyz="0 0 0"/>
      <inertia ixx="0.001" ixy="0.0" ixz="0.0" iyy="0.001" iyz="0.0" izz="0.001"/>
    </inertial>
    <visual>
      <origin rpy="0 0 0" xyz="0 0 0"/>
      <geometry>
        <mesh filename="package://robotino_description/meshes/kclhand/left_finger_upper_link.STL"/>
      </geometry>
      <material name="">
        <color rgba="0.79216 0.81961 0.93333 1"/>
      </material>
    </visual>
    <collision>
      <origin rpy="0 0 0" xyz="0 0 0"/>
      <geometry>
        <mesh filename="package://robotino_description/meshes/kclhand/left_finger_upper_link.STL"/>
      </geometry>
    </collision>
  </link>
  <joint name="hand_right_crank_base_joint" type="continuous">
    <origin rpy="-5.5511E-17 -2.7756E-17 1.0472" xyz="0 0 0"/>
    <parent link="hand_base_link"/>
    <child link="hand_right_crank"/>
    <axis xyz="0 0 1"/>
  </joint>
  <link name="hand_right_crank">
    <inertial>
      <mass value="0.01"/>
      <origin xyz="0 0 0"/>
      <inertia ixx="0.001" ixy="0.0" ixz="0.0" iyy="0.001" iyz="0.0" izz="0.001"/>
    </inertial>
    <visual>
      <origin rpy="0 0 0" xyz="0 0 0"/>
      <geometry>
        <mesh filename="package://robotino_description/meshes/kclhand/right_crank.STL"/>
      </geometry>
      <material name="">
        <color rgba="0.79216 0.81961 0.93333 1"/>
      </material>
    </visual>
    <collision>
      <origin rpy="0 0 0" xyz="0 0 0"/>
      <geometry>
        <mesh filename="package://robotino_description/meshes/kclhand/right_crank.STL"/>
      </geometry>
    </collision>
  </link>
  <joint name="hand_right_coupler_crank_joint" type="continuous">
    <origin rpy="0.40154 -0.63113 -0.62376" xyz="0 0 0"/>
    <parent link="hand_right_crank"/>
    <child link="hand_right_coupler"/>
    <axis xyz="0 0 1"/>
  </joint>
  <link name="hand_right_coupler">
    <inertial>
      <mass value="0.01"/>
      <origin xyz="0 0 0"/>
      <inertia ixx="0.001" ixy="0.0" ixz="0.0" iyy="0.001" iyz="0.0" izz="0.001"/>
    </inertial>
    <visual>
      <origin rpy="0 0 0" xyz="0 0 0"/>
      <geometry>
        <mesh filename="package://robotino_description/meshes/kclhand/right_coupler.STL"/>
      </geometry>
      <material name="">
        <color rgba="0.79216 0.81961 0.93333 1"/>
      </material>
    </visual>
    <collision>
      <origin rpy="0 0 0" xyz="0 0 0"/>
      <geometry>
        <mesh filename="package://robotino_description/meshes/kclhand/right_coupler.STL"/>
      </geometry>
    </collision>
  </link>
  <joint name="hand_right_finger_lower_joint" type="continuous">
    <origin rpy="-1.9199 -2.047E-16 1.5708" xyz="-0.016246 0.021 0.044635"/>
    <parent link="hand_right_coupler"/>
    <child link="hand_right_finger_lower_link"/>
    <axis xyz="0 0 1"/>
  </joint>
  <link name="hand_right_finger_lower_link">
    <inertial>
      <mass value="0.01"/>
      <origin xyz="0 0 0"/>
      <inertia ixx="0.001" ixy="0.0" ixz="0.0" iyy="0.001" iyz="0.0" izz="0.001"/>
    </inertial>
    <visual>
      <origin rpy="0 0 0" xyz="0 0 0"/>
      <geometry>
        <mesh filename="package://robotino_description/meshes/kclhand/right_finger_lower_link.STL"/>
      </geometry>
      <material name="">
        <color rgba="0.79216 0.81961 0.93333 1"/>
      </material>
    </visual>
    <collision>
      <origin rpy="0 0 0" xyz="0 0 0"/>
      <geometry>
        <mesh filename="package://robotino_description/meshes/kclhand/right_finger_lower_link.STL"/>
      </geometry>
    </collision>
  </link>
  <joint name="hand_right_finger_upper_joint" type="continuous">
    <origin rpy="4.4409E-16 -2.9143E-16 0.7854" xyz="0.05 0 0"/>
    <parent link="hand_right_finger_lower_link"/>
    <child link="hand_right_finger_upper_link"/>
    <axis xyz="0 0 1"/>
  </joint>
  <link name="hand_right_finger_upper_link">
    <inertial>
      <mass value="0.01"/>
      <origin xyz="0 0 0"/>
      <inertia ixx="0.001" ixy="0.0" ixz="0.0" iyy="0.001" iyz="0.0" izz="0.001"/>
    </inertial>
    <visual>
      <origin rpy="0 0 0" xyz="0 0 0"/>
      <geometry>
        <mesh filename="package://robotino_description/meshes/kclhand/right_finger_upper_link.STL"/>
      </geometry>
      <material name="">
        <color rgba="0.792156862745098 0.819607843137255 0.933333333333333 1"/>
      </material>
    </visual>
    <collision>
      <origin rpy="0 0 0" xyz="0 0 0"/>
      <geometry>
        <mesh filename="package://robotino_description/meshes/kclhand/right_finger_upper_link.STL"/>
      </geometry>
    </collision>
  </link>
  <joint name="hand_cableCanal_joint" type="fixed">
    <origin rpy="0 0 0" xyz="0.07 0.06 0"/>
    <parent link="hand_wrist_link"/>
    <child link="hand_cableCanal_link"/>
  </joint>
  <link name="hand_cableCanal_link">
    <inertial>
      <mass value="0.01"/>
      <origin xyz="0 0 0"/>
      <inertia ixx="0.001" ixy="0.0" ixz="0.0" iyy="0.001" iyz="0.0" izz="0.001"/>
    </inertial>
    <visual>
      <origin rpy="0 0 0" xyz="0 0 0"/>
      <geometry>
        <box size="0.0 0.0 0.0"/>
      </geometry>
      <material name="">
        <color rgba="0.79216 0.81961 0.93333 1"/>
      </material>
    </visual>
    <collision>
      <origin rpy="0 0 0" xyz="0 0 0"/>
      <geometry>
        <mesh filename="package://robotino_description/meshes/kclhand/cableCanalCollision.stl"/>
      </geometry>
    </collision>
  </link>
</robot>

